Workbook

Sheet Usuarios
A1: ID | B1: Nombre | C1: Primer Apellido | D1: Segundo Apellido | E1: RUT | F1: Telefono | G1: Email | H1: Direccion | I1: Fecha Incorporacion | J1: Integrantes Hogar | K1: Estado | L1: Observaciones
A2: 1 | B2: Nancy | C2: Zuñiga | D2: Villarroel | E2: 9797809-3 | F2: 988584908 | H2: Pasaje Las Rosas #309 | K2: Activo
A3: 2 | B3: Gabriel | C3: Barria | D3: Zuñiga | E3: 19175724-6 | F3: 973550328 | H3: Pasaje los Claveles S/N | J3: 3 | K3: Activo
A4: 3 | B4: Gino | C4: Reyes | E4: 13062892-3 | F4: 976087017 | K4: Activo
A5: 4 | B5: Cristian | C5: Oyarzo | E5: 18910875-3 | F5: 988515396 | K5: Activo
A6: 5 | B6: Marisol | C6: Castro | F6: 976006959 | K6: Activo
A7: 6 | B7: Mauricio | C7: Muñoz | F7: 968619494 | K7: Activo
A8: 7 | B8: Marcelo | C8: Millanao | F8: 956400315 | K8: Activo
A9: 8 | B9: Gabriel | C9: Farias | F9: 995153542 | K9: Activo
A10: 9 | B10: Maria | C10: Marin | F10: 968619494 | K10: Activo
A11: 10 | B11: David | C11: Cartes | F11: 957124563 | K11: Activo
A12: 11 | B12: Miguel | C12: Ñanco | F12: 987177967 | K12: Activo
A13: 12 | B13: Pedro | C13: Contreras | F13: 989964614 | K13: Inactivo
A14: 13 | B14: Carlos | C14: Gamin | F14: 958180175 | K14: Activo
A15: 14 | B15: Ramona | C15: Mansilla | K15: Activo
A16: 15 | B16: Sandra | C16: Mancilla | D16: Merino | K16: Activo
A17: 16 | B17: Carlos | C17: Agüero | F17: 968603541 | K17: Activo
A18: 17 | B18: Joaquin | C18: Claramunt | F18: 986597010 | K18: Activo
A19: 18 | B19: Nelson | C19: Mansilla | F19: 965202900 | K19: Activo
A20: 19 | B20: Eduardo | C20: Chavez | F20: 976201354 | K20: Activo
A21: 20 | B21: Juan | C21: Chavez | F21: 976201354 | K21: Activo
A22: 21 | B22: Luis | C22: Martinez | K22: Activo
A23: 22 | B23: Yuri | C23: Millaquen | F23: 976087017 | K23: Activo
A24: 23 | B24: Carlos | C24: Nahuelpan | F24: 992904575 | K24: Activo
A25: 24 | B25: Maria | C25: Velasquez | D25: Miranda | F25: 976065837 | K25: Activo
A26: 25 | B26: Inés | C26: Velasquez | K26: Activo
A27: 26 | B27: Guido | C27: Quintuy | F27: 997031231 | H27: Frutería | K27: Inactivo
A28: 27 | B28: Pedro | C28: Almonacid | K28: Activo
A29: 28 | B29: Nora | C29: Ñanco | K29: Activo
A30: 29 | B30: Miriam | C30: Alvarado | F30: 998962803 | K30: Activo
A31: 30 | B31: Luz | C31: Maldonado | F31: 965913448 | K31: Activo
A32: 31 | B32: Patricia | C32: Carcamo | D32: Gonzales | F32: 996147837 | K32: Activo
A33: 32 | B33: Natividad | C33: Soto | F33: 985961781 | K33: Activo
A34: 33 | B34: Maria Oliva | C34: Soto | D34: Almonacid | F34: 994727047 | K34: Activo
A35: 34 | B35: Vanesa | C35: Aguilar | F35: 977891512 | K35: Activo
A36: 35 | B36: José | C36: Paredes | K36: Activo
A37: 36 | B37: Danilo | C37: Soto | D37: Soto | K37: Activo
A38: 37 | B38: Patricio | C38: Alvarez | D38: Mancilla | K38: Activo
A39: 38 | B39: Norma | C39: Sanchez | F39: 979958848 | K39: Activo
A40: 39 | B40: Gloria | C40: Alvarez | K40: Activo
...

Sheet Plantilla
A1: ID | B1: Nombre | C1: Lectura_Anterior | D1: Lectura_Actual | E1: Consumo_m3 | F1: Tarifa_m3 | G1: Subtotal_Consumo | H1: Cargo_Fijo | I1: Total_Factura | J1: Fecha_Lectura | K1: Lectura Tomada | L1: Estado_Pago | M1: Monto_Pagado | N1: Fecha_Pago | O1: Forma_Pago | P1: Saldo_Pendiente | Q1: comprobante_link
A2: 41 | B2: =Usuarios!B42 & " " & Usuarios!C42 & " " & Usuarios!D42 -> Astrid Gomez | C2: =INDEX(INDIRECT("'" & TEXT(EDATE(J2,-2),"mm-yyyy") & "'!D:D"), MATCH(A2,INDIRECT("'" & TEXT(EDATE(J2,-2),"mm-yyyy") & "'!A:A"),0)) -> #NUM! | E2: =D2-C2 -> #NUM! | F2: 1182.6 | G2: =E2*F2 -> #NUM! | H2: 5000 | I2: =E2*F2+H2 -> #NUM! | K2: NO | L2: PENDIENTE | M2: =IF(L2="Pagado", I2, 0) -> 0 | P2: =IF(L2="NO APLICA",0, (I2-M2)) -> #NUM!
A3: 16 | B3: =Usuarios!B17 & " " & Usuarios!C17 & " " & Usuarios!D17 -> Carlos Agüero | C3: =INDEX(INDIRECT("'" & TEXT(EDATE(J3,-2),"mm-yyyy") & "'!D:D"), MATCH(A3,INDIRECT("'" & TEXT(EDATE(J3,-2),"mm-yyyy") & "'!A:A"),0)) -> #NUM! | E3: =D3-C3 -> #NUM! | F3: 1182.6 | G3: =E3*F3 -> #NUM! | H3: 5000 | I3: =E3*F3+H3 -> #NUM! | K3: NO | L3: PENDIENTE | M3: =IF(L3="Pagado", I3, 0) -> 0 | P3: =IF(L3="NO APLICA",0, (I3-M3)) -> #NUM!
A4: 13 | B4: =Usuarios!B14 & " " & Usuarios!C14 & " " & Usuarios!D14 -> Carlos Gamin | C4: =INDEX(INDIRECT("'" & TEXT(EDATE(J4,-2),"mm-yyyy") & "'!D:D"), MATCH(A4,INDIRECT("'" & TEXT(EDATE(J4,-2),"mm-yyyy") & "'!A:A"),0)) -> #NUM! | E4: =D4-C4 -> #NUM! | F4: 1182.6 | G4: =E4*F4 -> #NUM! | H4: 5000 | I4: =E4*F4+H4 -> #NUM! | K4: NO | L4: PENDIENTE | M4: =IF(L4="Pagado", I4, 0) -> 0 | P4: =IF(L4="NO APLICA",0, (I4-M4)) -> #NUM!
A5: 23 | B5: =Usuarios!B24 & " " & Usuarios!C24 & " " & Usuarios!D24 -> Carlos Nahuelpan | C5: =INDEX(INDIRECT("'" & TEXT(EDATE(J5,-2),"mm-yyyy") & "'!D:D"), MATCH(A5,INDIRECT("'" & TEXT(EDATE(J5,-2),"mm-yyyy") & "'!A:A"),0)) -> #NUM! | E5: =D5-C5 -> #NUM! | F5: 1182.6 | G5: =E5*F5 -> #NUM! | H5: 5000 | I5: =E5*F5+H5 -> #NUM! | K5: NO | L5: PENDIENTE | M5: =IF(L5="Pagado", I5, 0) -> 0 | P5: =IF(L5="NO APLICA",0, (I5-M5)) -> #NUM!
A6: 4 | B6: =Usuarios!B5 & " " & Usuarios!C5 & " " & Usuarios!D5 -> Cristian Oyarzo | C6: =INDEX(INDIRECT("'" & TEXT(EDATE(J6,-2),"mm-yyyy") & "'!D:D"), MATCH(A6,INDIRECT("'" & TEXT(EDATE(J6,-2),"mm-yyyy") & "'!A:A"),0)) -> #NUM! | E6: =D6-C6 -> #NUM! | F6: 1182.6 | G6: =E6*F6 -> #NUM! | H6: 5000 | I6: =E6*F6+H6 -> #NUM! | K6: NO | L6: PENDIENTE | M6: =IF(L6="Pagado", I6, 0) -> 0 | P6: =IF(L6="NO APLICA",0, (I6-M6)) -> #NUM!
A7: 36 | B7: =Usuarios!B37 & " " & Usuarios!C37 & " " & Usuarios!D37 -> Danilo Soto Soto | C7: =INDEX(INDIRECT("'" & TEXT(EDATE(J7,-2),"mm-yyyy") & "'!D:D"), MATCH(A7,INDIRECT("'" & TEXT(EDATE(J7,-2),"mm-yyyy") & "'!A:A"),0)) -> #NUM! | E7: =D7-C7 -> #NUM! | F7: 1182.6 | G7: =E7*F7 -> #NUM! | H7: 5000 | I7: =E7*F7+H7 -> #NUM! | K7: NO | L7: PENDIENTE | M7: =IF(L7="Pagado", I7, 0) -> 0 | P7: =IF(L7="NO APLICA",0, (I7-M7)) -> #NUM!
A8: 10 | B8: =Usuarios!B11 & " " & Usuarios!C11 & " " & Usuarios!D11 -> David Cartes | C8: =INDEX(INDIRECT("'" & TEXT(EDATE(J8,-2),"mm-yyyy") & "'!D:D"), MATCH(A8,INDIRECT("'" & TEXT(EDATE(J8,-2),"mm-yyyy") & "'!A:A"),0)) -> #NUM! | E8: =D8-C8 -> #NUM! | F8: 1182.6 | G8: =E8*F8 -> #NUM! | H8: 5000 | I8: =E8*F8+H8 -> #NUM! | K8: NO | L8: PENDIENTE | M8: =IF(L8="Pagado", I8, 0) -> 0 | P8: =IF(L8="NO APLICA",0, (I8-M8)) -> #NUM!
A9: 19 | B9: =Usuarios!B20 & " " & Usuarios!C20 & " " & Usuarios!D20 -> Eduardo Chavez | C9: =INDEX(INDIRECT("'" & TEXT(EDATE(J9,-2),"mm-yyyy") & "'!D:D"), MATCH(A9,INDIRECT("'" & TEXT(EDATE(J9,-2),"mm-yyyy") & "'!A:A"),0)) -> #NUM! | E9: =D9-C9 -> #NUM! | F9: 1182.6 | G9: =E9*F9 -> #NUM! | H9: 5000 | I9: =E9*F9+H9 -> #NUM! | K9: NO | L9: PENDIENTE | M9: =IF(L9="Pagado", I9, 0) -> 0 | P9: =IF(L9="NO APLICA",0, (I9-M9)) -> #NUM!
A10: 52 | B10: =Usuarios!B53 & " " & Usuarios!C53 & " " & Usuarios!D53 -> Esteban Oyarzo Levil | C10: =INDEX(INDIRECT("'" & TEXT(EDATE(J10,-2),"mm-yyyy") & "'!D:D"), MATCH(A10,INDIRECT("'" & TEXT(EDATE(J10,-2),"mm-yyyy") & "'!A:A"),0)) -> #NUM! | E10: =D10-C10 -> #NUM! | F10: 1182.6 | G10: =E10*F10 -> #NUM! | H10: 5000 | I10: =E10*F10+H10 -> #NUM! | K10: NO | L10: PENDIENTE | M10: =IF(L10="Pagado", I10, 0) -> 0 | P10: =IF(L10="NO APLICA",0, (I10-M10)) -> #NUM!
A11: 8 | B11: =Usuarios!B9 & " " & Usuarios!C9 & " " & Usuarios!D9 -> Gabriel Farias | C11: =INDEX(INDIRECT("'" & TEXT(EDATE(J11,-2),"mm-yyyy") & "'!D:D"), MATCH(A11,INDIRECT("'" & TEXT(EDATE(J11,-2),"mm-yyyy") & "'!A:A"),0)) -> #NUM! | E11: =D11-C11 -> #NUM! | F11: 1182.6 | G11: =E11*F11 -> #NUM! | H11: 5000 | I11: =E11*F11+H11 -> #NUM! | K11: NO | L11: PENDIENTE | M11: =IF(L11="Pagado", I11, 0) -> 0 | P11: =IF(L11="NO APLICA",0, (I11-M11)) -> #NUM!
A12: 2 | B12: =Usuarios!B3 & " " & Usuarios!C3 & " " & Usuarios!D3 -> Gabriel Barria Zuñiga | C12: =INDEX(INDIRECT("'" & TEXT(EDATE(J12,-2),"mm-yyyy") & "'!D:D"), MATCH(A12,INDIRECT("'" & TEXT(EDATE(J12,-2),"mm-yyyy") & "'!A:A"),0)) -> #NUM! | E12: =D12-C12 -> #NUM! | F12: 1182.6 | G12: =E12*F12 -> #NUM! | H12: 5000 | I12: =E12*F12+H12 -> #NUM! | K12: NO | L12: PENDIENTE | M12: =IF(L12="Pagado", I12, 0) -> 0 | P12: =IF(L12="NO APLICA",0, (I12-M12)) -> #NUM!
A13: 3 | B13: =Usuarios!B4 & " " & Usuarios!C4 & " " & Usuarios!D4 -> Gino Reyes | C13: =INDEX(INDIRECT("'" & TEXT(EDATE(J13,-2),"mm-yyyy") & "'!D:D"), MATCH(A13,INDIRECT("'" & TEXT(EDATE(J13,-2),"mm-yyyy") & "'!A:A"),0)) -> #NUM! | E13: =D13-C13 -> #NUM! | F13: 1182.6 | G13: =E13*F13 -> #NUM! | H13: 5000 | I13: =E13*F13+H13 -> #NUM! | K13: NO | L13: PENDIENTE | M13: =IF(L13="Pagado", I13, 0) -> 0 | P13: =IF(L13="NO APLICA",0, (I13-M13)) -> #NUM!
A14: 39 | B14: =Usuarios!B40 & " " & Usuarios!C40 & " " & Usuarios!D40 -> Gloria Alvarez | C14: =INDEX(INDIRECT("'" & TEXT(EDATE(J14,-2),"mm-yyyy") & "'!D:D"), MATCH(A14,INDIRECT("'" & TEXT(EDATE(J14,-2),"mm-yyyy") & "'!A:A"),0)) -> #NUM! | E14: =D14-C14 -> #NUM! | F14: 1182.6 | G14: =E14*F14 -> #NUM! | H14: 5000 | I14: =E14*F14+H14 -> #NUM! | K14: NO | L14: PENDIENTE | M14: =IF(L14="Pagado", I14, 0) -> 0 | P14: =IF(L14="NO APLICA",0, (I14-M14)) -> #NUM!
A15: 40 | B15: =Usuarios!B41 & " " & Usuarios!C41 & " " & Usuarios!D41 -> Gloria Levil | C15: =INDEX(INDIRECT("'" & TEXT(EDATE(J15,-2),"mm-yyyy") & "'!D:D"), MATCH(A15,INDIRECT("'" & TEXT(EDATE(J15,-2),"mm-yyyy") & "'!A:A"),0)) -> #NUM! | E15: =D15-C15 -> #NUM! | F15: 1182.6 | G15: =E15*F15 -> #NUM! | H15: 5000 | I15: =E15*F15+H15 -> #NUM! | K15: NO | L15: PENDIENTE | M15: =IF(L15="Pagado", I15, 0) -> 0 | P15: =IF(L15="NO APLICA",0, (I15-M15)) -> #NUM!
A16: 50 | B16: =Usuarios!B51 & " " & Usuarios!C51 & " " & Usuarios!D51 -> Gloria Isamar Velasquez Almonacid | C16: =INDEX(INDIRECT("'" & TEXT(EDATE(J16,-2),"mm-yyyy") & "'!D:D"), MATCH(A16,INDIRECT("'" & TEXT(EDATE(J16,-2),"mm-yyyy") & "'!A:A"),0)) -> #NUM! | E16: =D16-C16 -> #NUM! | F16: 1182.6 | G16: =E16*F16 -> #NUM! | H16: 5000 | I16: =E16*F16+H16 -> #NUM! | K16: NO | L16: PENDIENTE | M16: =IF(L16="Pagado", I16, 0) -> 0 | P16: =IF(L16="NO APLICA",0, (I16-M16)) -> #NUM!
A17: 26 | B17: =Usuarios!B27 & " " & Usuarios!C27 & " " & Usuarios!D27 -> Guido Quintuy | C17: =INDEX(INDIRECT("'" & TEXT(EDATE(J17,-2),"mm-yyyy") & "'!D:D"), MATCH(A17,INDIRECT("'" & TEXT(EDATE(J17,-2),"mm-yyyy") & "'!A:A"),0)) -> #NUM! | K17: NO | L17: PENDIENTE
A18: 55 | B18: =Usuarios!B56 & " " & Usuarios!C56 & " " & Usuarios!D56 -> Guido Quintuy - Sitio vacío | C18: =INDEX(INDIRECT("'" & TEXT(EDATE(J18,-2),"mm-yyyy") & "'!D:D"), MATCH(A18,INDIRECT("'" & TEXT(EDATE(J18,-2),"mm-yyyy") & "'!A:A"),0)) -> #NUM! | E18: =D18-C18 -> #NUM! | F18: 1182.6 | G18: =E18*F18 -> #NUM! | H18: 5000 | I18: =E18*F18+H18 -> #NUM! | K18: NO | L18: PENDIENTE | M18: =IF(L18="Pagado", I18, 0) -> 0 | P18: =IF(L18="NO APLICA",0, (I18-M18)) -> #NUM!
A19: 25 | B19: =Usuarios!B26 & " " & Usuarios!C26 & " " & Usuarios!D26 -> Inés Velasquez | C19: =INDEX(INDIRECT("'" & TEXT(EDATE(J19,-2),"mm-yyyy") & "'!D:D"), MATCH(A19,INDIRECT("'" & TEXT(EDATE(J19,-2),"mm-yyyy") & "'!A:A"),0)) -> #NUM! | E19: =D19-C19 -> #NUM! | F19: 1182.6 | G19: =E19*F19 -> #NUM! | H19: 5000 | I19: =E19*F19+H19 -> #NUM! | K19: NO | L19: PENDIENTE | M19: =IF(L19="Pagado", I19, 0) -> 0 | P19: =IF(L19="NO APLICA",0, (I19-M19)) -> #NUM!
A20: 17 | B20: =Usuarios!B18 & " " & Usuarios!C18 & " " & Usuarios!D18 -> Joaquin Claramunt | C20: =INDEX(INDIRECT("'" & TEXT(EDATE(J20,-2),"mm-yyyy") & "'!D:D"), MATCH(A20,INDIRECT("'" & TEXT(EDATE(J20,-2),"mm-yyyy") & "'!A:A"),0)) -> #NUM! | E20: =D20-C20 -> #NUM! | F20: 1182.6 | G20: =E20*F20 -> #NUM! | H20: 5000 | I20: =E20*F20+H20 -> #NUM! | K20: NO | L20: PENDIENTE | M20: =IF(L20="Pagado", I20, 0) -> 0 | P20: =IF(L20="NO APLICA",0, (I20-M20)) -> #NUM!
A21: 35 | B21: =Usuarios!B36 & " " & Usuarios!C36 & " " & Usuarios!D36 -> José Paredes | C21: =INDEX(INDIRECT("'" & TEXT(EDATE(J21,-2),"mm-yyyy") & "'!D:D"), MATCH(A21,INDIRECT("'" & TEXT(EDATE(J21,-2),"mm-yyyy") & "'!A:A"),0)) -> #NUM! | E21: =D21-C21 -> #NUM! | F21: 1182.6 | G21: =E21*F21 -> #NUM! | H21: 5000 | I21: =E21*F21+H21 -> #NUM! | K21: NO | L21: PENDIENTE | M21: =IF(L21="Pagado", I21, 0) -> 0 | P21: =IF(L21="NO APLICA",0, (I21-M21)) -> #NUM!
A22: 20 | B22: =Usuarios!B21 & " " & Usuarios!C21 & " " & Usuarios!D21 -> Juan Chavez | C22: =INDEX(INDIRECT("'" & TEXT(EDATE(J22,-2),"mm-yyyy") & "'!D:D"), MATCH(A22,INDIRECT("'" & TEXT(EDATE(J22,-2),"mm-yyyy") & "'!A:A"),0)) -> #NUM! | E22: =D22-C22 -> #NUM! | F22: 1182.6 | G22: =E22*F22 -> #NUM! | H22: 5000 | I22: =E22*F22+H22 -> #NUM! | K22: NO | L22: PENDIENTE | M22: =IF(L22="Pagado", I22, 0) -> 0 | P22: =IF(L22="NO APLICA",0, (I22-M22)) -> #NUM!
A23: 42 | B23: =Usuarios!B43 & " " & Usuarios!C43 & " " & Usuarios!D43 -> Leo Soto | C23: =INDEX(INDIRECT("'" & TEXT(EDATE(J23,-2),"mm-yyyy") & "'!D:D"), MATCH(A23,INDIRECT("'" & TEXT(EDATE(J23,-2),"mm-yyyy") & "'!A:A"),0)) -> #NUM! | E23: =D23-C23 -> #NUM! | F23: 1182.6 | G23: =E23*F23 -> #NUM! | H23: 5000 | I23: =E23*F23+H23 -> #NUM! | K23: NO | L23: PENDIENTE | M23: =IF(L23="Pagado", I23, 0) -> 0 | P23: =IF(L23="NO APLICA",0, (I23-M23)) -> #NUM!
A24: 57 | B24: =Usuarios!B58 & " " & Usuarios!C58 & " " & Usuarios!D58 -> Lishby Fuentes Diaz | C24: =INDEX(INDIRECT("'" & TEXT(EDATE(J24,-2),"mm-yyyy") & "'!D:D"), MATCH(A24,INDIRECT("'" & TEXT(EDATE(J24,-2),"mm-yyyy") & "'!A:A"),0)) -> #NUM! | E24: =D24-C24 -> #NUM! | F24: 1182.6 | G24: =E24*F24 -> #NUM! | H24: 5000 | I24: =E24*F24+H24 -> #NUM! | K24: NO | L24: PENDIENTE | M24: =IF(L24="Pagado", I24, 0) -> 0 | P24: =IF(L24="NO APLICA",0, (I24-M24)) -> #NUM!
A25: 48 | B25: =Usuarios!B49 & " " & Usuarios!C49 & " " & Usuarios!D49 -> Luis Vicente Mondaca Muñoz | C25: =INDEX(INDIRECT("'" & TEXT(EDATE(J25,-2),"mm-yyyy") & "'!D:D"), MATCH(A25,INDIRECT("'" & TEXT(EDATE(J25,-2),"mm-yyyy") & "'!A:A"),0)) -> #NUM! | E25: =D25-C25 -> #NUM! | F25: 1182.6 | G25: =E25*F25 -> #NUM! | H25: 5000 | I25: =E25*F25+H25 -> #NUM! | K25: NO | L25: PENDIENTE | M25: =IF(L25="Pagado", I25, 0) -> 0 | P25: =IF(L25="NO APLICA",0, (I25-M25)) -> #NUM!
A26: 30 | B26: =Usuarios!B31 & " " & Usuarios!C31 & " " & Usuarios!D31 -> Luz Maldonado | C26: =INDEX(INDIRECT("'" & TEXT(EDATE(J26,-2),"mm-yyyy") & "'!D:D"), MATCH(A26,INDIRECT("'" & TEXT(EDATE(J26,-2),"mm-yyyy") & "'!A:A"),0)) -> #NUM! | E26: =D26-C26 -> #NUM! | F26: 1182.6 | G26: =E26*F26 -> #NUM! | H26: 5000 | I26: =E26*F26+H26 -> #NUM! | K26: NO | L26: PENDIENTE | M26: =IF(L26="Pagado", I26, 0) -> 0 | P26: =IF(L26="NO APLICA",0, (I26-M26)) -> #NUM!
A27: 7 | B27: =Usuarios!B8 & " " & Usuarios!C8 & " " & Usuarios!D8 -> Marcelo Millanao | C27: =INDEX(INDIRECT("'" & TEXT(EDATE(J27,-2),"mm-yyyy") & "'!D:D"), MATCH(A27,INDIRECT("'" & TEXT(EDATE(J27,-2),"mm-yyyy") & "'!A:A"),0)) -> #NUM! | E27: =D27-C27 -> #NUM! | F27: 1182.6 | G27: =E27*F27 -> #NUM! | H27: 5000 | I27: =E27*F27+H27 -> #NUM! | K27: NO | L27: PENDIENTE | M27: =IF(L27="Pagado", I27, 0) -> 0 | P27: =IF(L27="NO APLICA",0, (I27-M27)) -> #NUM!
A28: 51 | B28: =Usuarios!B52 & " " & Usuarios!C52 & " " & Usuarios!D52 -> Maria Manquian | C28: =INDEX(INDIRECT("'" & TEXT(EDATE(J28,-2),"mm-yyyy") & "'!D:D"), MATCH(A28,INDIRECT("'" & TEXT(EDATE(J28,-2),"mm-yyyy") & "'!A:A"),0)) -> #NUM! | E28: =D28-C28 -> #NUM! | F28: 1182.6 | G28: =E28*F28 -> #NUM! | H28: 5000 | I28: =E28*F28+H28 -> #NUM! | K28: NO | L28: PENDIENTE | M28: =IF(L28="Pagado", I28, 0) -> 0 | P28: =IF(L28="NO APLICA",0, (I28-M28)) -> #NUM!
A29: 9 | B29: =Usuarios!B10 & " " & Usuarios!C10 & " " & Usuarios!D10 -> Maria Marin | C29: =INDEX(INDIRECT("'" & TEXT(EDATE(J29,-2),"mm-yyyy") & "'!D:D"), MATCH(A29,INDIRECT("'" & TEXT(EDATE(J29,-2),"mm-yyyy") & "'!A:A"),0)) -> #NUM! | E29: =D29-C29 -> #NUM! | F29: 1182.6 | G29: =E29*F29 -> #NUM! | H29: 5000 | I29: =E29*F29+H29 -> #NUM! | K29: NO | L29: PENDIENTE | M29: =IF(L29="Pagado", I29, 0) -> 0 | P29: =IF(L29="NO APLICA",0, (I29-M29)) -> #NUM!
A30: 33 | B30: =Usuarios!B34 & " " & Usuarios!C34 & " " & Usuarios!D34 -> Maria Oliva Soto Almonacid | C30: =INDEX(INDIRECT("'" & TEXT(EDATE(J30,-2),"mm-yyyy") & "'!D:D"), MATCH(A30,INDIRECT("'" & TEXT(EDATE(J30,-2),"mm-yyyy") & "'!A:A"),0)) -> #NUM! | E30: =D30-C30 -> #NUM! | F30: 1182.6 | G30: =E30*F30 -> #NUM! | H30: 5000 | I30: =E30*F30+H30 -> #NUM! | K30: NO | L30: PENDIENTE | M30: =IF(L30="Pagado", I30, 0) -> 0 | P30: =IF(L30="NO APLICA",0, (I30-M30)) -> #NUM!
A31: 44 | B31: =Usuarios!B45 & " " & Usuarios!C45 & " " & Usuarios!D45 -> María Sonia Quintui | C31: =INDEX(INDIRECT("'" & TEXT(EDATE(J31,-2),"mm-yyyy") & "'!D:D"), MATCH(A31,INDIRECT("'" & TEXT(EDATE(J31,-2),"mm-yyyy") & "'!A:A"),0)) -> #NUM! | E31: =D31-C31 -> #NUM! | F31: 1182.6 | G31: =E31*F31 -> #NUM! | H31: 5000 | I31: =E31*F31+H31 -> #NUM! | K31: NO | L31: PENDIENTE | M31: =IF(L31="Pagado", I31, 0) -> 0 | P31: =IF(L31="NO APLICA",0, (I31-M31)) -> #NUM!
A32: 24 | B32: =Usuarios!B25 & " " & Usuarios!C25 & " " & Usuarios!D25 -> Maria Velasquez Miranda | C32: =INDEX(INDIRECT("'" & TEXT(EDATE(J32,-2),"mm-yyyy") & "'!D:D"), MATCH(A32,INDIRECT("'" & TEXT(EDATE(J32,-2),"mm-yyyy") & "'!A:A"),0)) -> #NUM! | E32: =D32-C32 -> #NUM! | F32: 1182.6 | G32: =E32*F32 -> #NUM! | H32: 5000 | I32: =E32*F32+H32 -> #NUM! | K32: NO | L32: PENDIENTE | M32: =IF(L32="Pagado", I32, 0) -> 0 | P32: =IF(L32="NO APLICA",0, (I32-M32)) -> #NUM!
A33: 56 | B33: =Usuarios!B57 & " " & Usuarios!C57 & " " & Usuarios!D57 -> Mario Velasquez | C33: =INDEX(INDIRECT("'" & TEXT(EDATE(J33,-2),"mm-yyyy") & "'!D:D"), MATCH(A33,INDIRECT("'" & TEXT(EDATE(J33,-2),"mm-yyyy") & "'!A:A"),0)) -> #NUM! | E33: =D33-C33 -> #NUM! | F33: 1182.6 | G33: =E33*F33 -> #NUM! | H33: 5000 | I33: =E33*F33+H33 -> #NUM! | K33: NO | L33: PENDIENTE | M33: =IF(L33="Pagado", I33, 0) -> 0 | P33: =IF(L33="NO APLICA",0, (I33-M33)) -> #NUM!
A34: 5 | B34: =Usuarios!B6 & " " & Usuarios!C6 & " " & Usuarios!D6 -> Marisol Castro | C34: =INDEX(INDIRECT("'" & TEXT(EDATE(J34,-2),"mm-yyyy") & "'!D:D"), MATCH(A34,INDIRECT("'" & TEXT(EDATE(J34,-2),"mm-yyyy") & "'!A:A"),0)) -> #NUM! | E34: =D34-C34 -> #NUM! | F34: 1182.6 | G34: =E34*F34 -> #NUM! | H34: 5000 | I34: =E34*F34+H34 -> #NUM! | K34: NO | L34: PENDIENTE | M34: =IF(L34="Pagado", I34, 0) -> 0 | P34: =IF(L34="NO APLICA",0, (I34-M34)) -> #NUM!
A35: 6 | B35: =Usuarios!B7 & " " & Usuarios!C7 & " " & Usuarios!D7 -> Mauricio Muñoz | C35: =INDEX(INDIRECT("'" & TEXT(EDATE(J35,-2),"mm-yyyy") & "'!D:D"), MATCH(A35,INDIRECT("'" & TEXT(EDATE(J35,-2),"mm-yyyy") & "'!A:A"),0)) -> #NUM! | E35: =D35-C35 -> #NUM! | F35: 1182.6 | G35: =E35*F35 -> #NUM! | H35: 5000 | I35: =E35*F35+H35 -> #NUM! | K35: NO | L35: PENDIENTE | M35: =IF(L35="Pagado", I35, 0) -> 0 | P35: =IF(L35="NO APLICA",0, (I35-M35)) -> #NUM!
A36: 46 | B36: =Usuarios!B47 & " " & Usuarios!C47 & " " & Usuarios!D47 -> Mauricio Muñoz taller | C36: =INDEX(INDIRECT("'" & TEXT(EDATE(J36,-2),"mm-yyyy") & "'!D:D"), MATCH(A36,INDIRECT("'" & TEXT(EDATE(J36,-2),"mm-yyyy") & "'!A:A"),0)) -> #NUM! | E36: =D36-C36 -> #NUM! | F36: 1182.6 | G36: =E36*F36 -> #NUM! | H36: 5000 | I36: =E36*F36+H36 -> #NUM! | K36: NO | L36: PENDIENTE | M36: =IF(L36="Pagado", I36, 0) -> 0 | P36: =IF(L36="NO APLICA",0, (I36-M36)) -> #NUM!
A37: 11 | B37: =Usuarios!B12 & " " & Usuarios!C12 & " " & Usuarios!D12 -> Miguel Ñanco | C37: =INDEX(INDIRECT("'" & TEXT(EDATE(J37,-2),"mm-yyyy") & "'!D:D"), MATCH(A37,INDIRECT("'" & TEXT(EDATE(J37,-2),"mm-yyyy") & "'!A:A"),0)) -> #NUM! | E37: =D37-C37 -> #NUM! | F37: 1182.6 | G37: =E37*F37 -> #NUM! | H37: 5000 | I37: =E37*F37+H37 -> #NUM! | K37: NO | L37: PENDIENTE | M37: =IF(L37="Pagado", I37, 0) -> 0 | P37: =IF(L37="NO APLICA",0, (I37-M37)) -> #NUM!
A38: 29 | B38: =Usuarios!B30 & " " & Usuarios!C30 & " " & Usuarios!D30 -> Miriam Alvarado | C38: =INDEX(INDIRECT("'" & TEXT(EDATE(J38,-2),"mm-yyyy") & "'!D:D"), MATCH(A38,INDIRECT("'" & TEXT(EDATE(J38,-2),"mm-yyyy") & "'!A:A"),0)) -> #NUM! | E38: =D38-C38 -> #NUM! | F38: 1182.6 | G38: =E38*F38 -> #NUM! | H38: 5000 | I38: =E38*F38+H38 -> #NUM! | K38: NO | L38: PENDIENTE | M38: =IF(L38="Pagado", I38, 0) -> 0 | P38: =IF(L38="NO APLICA",0, (I38-M38)) -> #NUM!
A39: 45 | B39: =Usuarios!B46 & " " & Usuarios!C46 & " " & Usuarios!D46 -> Monica Cuello | C39: =INDEX(INDIRECT("'" & TEXT(EDATE(J39,-2),"mm-yyyy") & "'!D:D"), MATCH(A39,INDIRECT("'" & TEXT(EDATE(J39,-2),"mm-yyyy") & "'!A:A"),0)) -> #NUM! | E39: =D39-C39 -> #NUM! | F39: 1182.6 | G39: =E39*F39 -> #NUM! | H39: 5000 | I39: =E39*F39+H39 -> #NUM! | K39: NO | L39: PENDIENTE | M39: =IF(L39="Pagado", I39, 0) -> 0 | P39: =IF(L39="NO APLICA",0, (I39-M39)) -> #NUM!
A40: 1 | B40: =Usuarios!B2 & " " & Usuarios!C2 & " " & Usuarios!D2 -> Nancy Zuñiga Villarroel | C40: =INDEX(INDIRECT("'" & TEXT(EDATE(J40,-2),"mm-yyyy") & "'!D:D"), MATCH(A40,INDIRECT("'" & TEXT(EDATE(J40,-2),"mm-yyyy") & "'!A:A"),0)) -> #NUM! | E40: =D40-C40 -> #NUM! | F40: 1182.6 | G40: =E40*F40 -> #NUM! | H40: 5000 | I40: =E40*F40+H40 -> #NUM! | K40: NO | L40: PENDIENTE | M40: =IF(L40="Pagado", I40, 0) -> 0 | P40: =IF(L40="NO APLICA",0, (I40-M40)) -> #NUM!
...

Sheet 01-2025
A1: ID | B1: Nombre | C1: Lectura_Anterior | D1: Lectura_Actual | E1: Consumo_m3 | F1: Tarifa_m3 | G1: Subtotal_Consumo | H1: Cargo_Fijo | I1: Total_Factura | J1: Fecha_Lectura | K1: Periodo | L1: Estado_Pago | M1: Monto_Pagado | N1: Fecha_Pago | O1: Forma_Pago | P1: Saldo_Pendiente | Q1: comprobante_link
A2: 1 | B2: =Usuarios!B2 & " " & Usuarios!C2 & " " & Usuarios!D2 -> Nancy Zuñiga Villarroel | C2: 152 | D2: 165 | E2: =D2-C2 -> 13 | F2: 1182.6 | G2: =E2*F2 -> 15373.8 | H2: 5000 | I2: =E2*F2+H2 -> 20373.8 | L2: PAGADO | M2: =IF(L2="Pagado", I2, 0) -> 20373.8 | P2: =IF(L2="NO APLICA",0, (I2-M2)) -> 0
A3: 2 | B3: =Usuarios!B3 & " " & Usuarios!C3 & " " & Usuarios!D3 -> Gabriel Barria Zuñiga | C3: 235 | D3: 253 | E3: =D3-C3 -> 18 | F3: 1182.6 | G3: =E3*F3 -> 21286.8 | H3: 5000 | I3: =E3*F3+H3 -> 26286.8 | L3: PAGADO | M3: =IF(L3="Pagado", I3, 0) -> 26286.8 | P3: =IF(L3="NO APLICA",0, (I3-M3)) -> 0
A4: 3 | B4: =Usuarios!B4 & " " & Usuarios!C4 & " " & Usuarios!D4 -> Gino Reyes | C4: 55 | D4: 55 | E4: =D4-C4 -> 0 | F4: 1182.6 | G4: =E4*F4 -> 0 | H4: 5000 | I4: =E4*F4+H4 -> 5000 | L4: PAGADO | M4: =IF(L4="Pagado", I4, 0) -> 5000 | P4: =IF(L4="NO APLICA",0, (I4-M4)) -> 0
A5: 4 | B5: =Usuarios!B5 & " " & Usuarios!C5 & " " & Usuarios!D5 -> Cristian Oyarzo | C5: 390 | D5: 420 | E5: =D5-C5 -> 30 | F5: 1182.6 | G5: =E5*F5 -> 35478 | H5: 5000 | I5: =E5*F5+H5 -> 40478 | L5: PAGADO | M5: =IF(L5="Pagado", I5, 0) -> 40478 | P5: =IF(L5="NO APLICA",0, (I5-M5)) -> 0
A6: 5 | B6: =Usuarios!B6 & " " & Usuarios!C6 & " " & Usuarios!D6 -> Marisol Castro | C6: 81 | D6: 88 | E6: =D6-C6 -> 7 | F6: 1182.6 | G6: =E6*F6 -> 8278.2 | H6: 5000 | I6: =E6*F6+H6 -> 13278.2 | L6: PAGADO | M6: =IF(L6="Pagado", I6, 0) -> 13278.2 | P6: =IF(L6="NO APLICA",0, (I6-M6)) -> 0
A7: 6 | B7: =Usuarios!B7 & " " & Usuarios!C7 & " " & Usuarios!D7 -> Mauricio Muñoz | C7: 163 | D7: 174 | E7: =D7-C7 -> 11 | F7: 1182.6 | G7: =E7*F7 -> 13008.6 | H7: 5000 | I7: =E7*F7+H7 -> 18008.6 | L7: PAGADO | M7: =IF(L7="Pagado", I7, 0) -> 18008.6 | P7: =IF(L7="NO APLICA",0, (I7-M7)) -> 0
A8: 7 | B8: =Usuarios!B8 & " " & Usuarios!C8 & " " & Usuarios!D8 -> Marcelo Millanao | C8: 200 | D8: 211 | E8: =D8-C8 -> 11 | F8: 1182.6 | G8: =E8*F8 -> 13008.6 | H8: 5000 | I8: =E8*F8+H8 -> 18008.6 | L8: PAGADO | M8: =IF(L8="Pagado", I8, 0) -> 18008.6 | P8: =IF(L8="NO APLICA",0, (I8-M8)) -> 0
A9: 8 | B9: =Usuarios!B9 & " " & Usuarios!C9 & " " & Usuarios!D9 -> Gabriel Farias | C9: 353 | D9: 379 | E9: =D9-C9 -> 26 | F9: 1182.6 | G9: =E9*F9 -> 30747.6 | H9: 5000 | I9: =E9*F9+H9 -> 35747.6 | L9: PAGADO | M9: =IF(L9="Pagado", I9, 0) -> 35747.6 | P9: =IF(L9="NO APLICA",0, (I9-M9)) -> 0
A10: 9 | B10: =Usuarios!B10 & " " & Usuarios!C10 & " " & Usuarios!D10 -> Maria Marin | C10: 126 | D10: 137 | E10: =D10-C10 -> 11 | F10: 1182.6 | G10: =E10*F10 -> 13008.6 | H10: 5000 | I10: =E10*F10+H10 -> 18008.6 | L10: PAGADO | M10: =IF(L10="Pagado", I10, 0) -> 18008.6 | P10: =IF(L10="NO APLICA",0, (I10-M10)) -> 0
A11: 10 | B11: =Usuarios!B11 & " " & Usuarios!C11 & " " & Usuarios!D11 -> David Cartes | C11: 90 | D11: 97 | E11: =D11-C11 -> 7 | F11: 1182.6 | G11: =E11*F11 -> 8278.2 | H11: 5000 | I11: =E11*F11+H11 -> 13278.2 | L11: PAGADO | M11: =IF(L11="Pagado", I11, 0) -> 13278.2 | P11: =IF(L11="NO APLICA",0, (I11-M11)) -> 0
A12: 11 | B12: =Usuarios!B12 & " " & Usuarios!C12 & " " & Usuarios!D12 -> Miguel Ñanco | C12: 159 | D12: 189 | E12: =D12-C12 -> 30 | F12: 1182.6 | G12: =E12*F12 -> 35478 | H12: 5000 | I12: =E12*F12+H12 -> 40478 | L12: PAGADO | M12: =IF(L12="Pagado", I12, 0) -> 40478 | P12: =IF(L12="NO APLICA",0, (I12-M12)) -> 0
A13: 12 | B13: =Usuarios!B13 & " " & Usuarios!C13 & " " & Usuarios!D13 -> Pedro Contreras | C13: 90 | D13: 97 | E13: =D13-C13 -> 7 | F13: 1182.6 | G13: =E13*F13 -> 8278.2 | H13: 5000 | I13: =E13*F13+H13 -> 13278.2 | L13: PAGADO | M13: =IF(L13="Pagado", I13, 0) -> 13278.2 | P13: =IF(L13="NO APLICA",0, (I13-M13)) -> 0
... A21: 20 | B21: =Usuarios!B21 & " " & Usuarios!C21 & " " & Usuarios!D21 -> Juan Chavez | C21: 20 | D21: 21 | E21: =D21-C21 -> 1 | F21: 1182.6 | G21: =E21*F21 -> 1182.6 | H21: 5000 | I21: =E21*F21+H21 -> 6182.6 | L21: PAGADO | M21: =IF(L21="Pagado", I21, 0) -> 6182.6 | P21: =IF(L21="NO APLICA",0, (I21-M21)) -> 0
A22: 21
A23: 22 | B23: =Usuarios!B23 & " " & Usuarios!C23 & " " & Usuarios!D23 -> Yuri Millaquen | C23: 119 | D23: 130 | E23: =D23-C23 -> 11 | F23: 1182.6 | G23: =E23*F23 -> 13008.6 | H23: 5000 | I23: =E23*F23+H23 -> 18008.6 | L23: PAGADO | M23: =IF(L23="Pagado", I23, 0) -> 18008.6 | P23: =IF(L23="NO APLICA",0, (I23-M23)) -> 0
A24: 23 | B24: =Usuarios!B24 & " " & Usuarios!C24 & " " & Usuarios!D24 -> Carlos Nahuelpan | C24: 83 | D24: 92 | E24: =D24-C24 -> 9 | F24: 1182.6 | G24: =E24*F24 -> 10643.4 | H24: 5000 | I24: =E24*F24+H24 -> 15643.4 | L24: PAGADO | M24: =IF(L24="Pagado", I24, 0) -> 15643.4 | P24: =IF(L24="NO APLICA",0, (I24-M24)) -> 0
A25: 24 | B25: =Usuarios!B25 & " " & Usuarios!C25 & " " & Usuarios!D25 -> Maria Velasquez Miranda | C25: 184 | D25: 203 | E25: =D25-C25 -> 19 | F25: 1182.6 | G25: =E25*F25 -> 22469.4 | H25: 5000 | I25: =E25*F25+H25 -> 27469.4 | L25: PAGADO | M25: =IF(L25="Pagado", I25, 0) -> 27469.4 | P25: =IF(L25="NO APLICA",0, (I25-M25)) -> 0
A26: 25 | B26: =Usuarios!B26 & " " & Usuarios!C26 & " " & Usuarios!D26 -> Inés Velasquez | C26: 96 | D26: 100 | E26: =D26-C26 -> 4 | F26: 1182.6 | G26: =E26*F26 -> 4730.4 | H26: 5000 | I26: =E26*F26+H26 -> 9730.4 | L26: PAGADO | M26: =IF(L26="Pagado", I26, 0) -> 9730.4 | P26: =IF(L26="NO APLICA",0, (I26-M26)) -> 0
A27: 26 | B27: =Usuarios!B27 & " " & Usuarios!C27 & " " & Usuarios!D27 -> Guido Quintuy | C27: 109 | D27: 117 | E27: =D27-C27 -> 8 | F27: 1182.6 | G27: =E27*F27 -> 9460.8 | H27: 5000 | I27: =E27*F27+H27 -> 14460.8 | L27: PAGADO | M27: =IF(L27="Pagado", I27, 0) -> 14460.8 | P27: =IF(L27="NO APLICA",0, (I27-M27)) -> 0
A28: 27 | B28: =Usuarios!B28 & " " & Usuarios!C28 & " " & Usuarios!D28 -> Pedro Almonacid | C28: 160 | D28: 177 | E28: =D28-C28 -> 17 | F28: 1182.6 | G28: =E28*F28 -> 20104.2 | H28: 5000 | I28: =E28*F28+H28 -> 25104.2 | L28: PENDIENTE | M28: =IF(L28="Pagado", I28, 0) -> 0 | P28: =IF(L28="NO APLICA",0, (I28-M28)) -> 25104.2
A29: 28 | B29: =Usuarios!B29 & " " & Usuarios!C29 & " " & Usuarios!D29 -> Nora Ñanco | C29: 363 | D29: 381 | E29: =D29-C29 -> 18 | F29: 1182.6 | G29: =E29*F29 -> 21286.8 | H29: 5000 | I29: =E29*F29+H29 -> 26286.8 | L29: PAGADO | M29: =IF(L29="Pagado", I29, 0) -> 26286.8 | P29: =IF(L29="NO APLICA",0, (I29-M29)) -> 0
A30: 29 | B30: =Usuarios!B30 & " " & Usuarios!C30 & " " & Usuarios!D30 -> Miriam Alvarado | C30: 488 | D30: 515 | E30: =D30-C30 -> 27 | F30: 1182.6 | G30: =E30*F30 -> 31930.2 | H30: 5000 | I30: =E30*F30+H30 -> 36930.2 | L30: PAGADO | M30: =IF(L30="Pagado", I30, 0) -> 36930.2 | P30: =IF(L30="NO APLICA",0, (I30-M30)) -> 0
A31: 30 | B31: =Usuarios!B31 & " " & Usuarios!C31 & " " & Usuarios!D31 -> Luz Maldonado | C31: 5 | D31: 5 | E31: =D31-C31 -> 0 | F31: 1182.6 | G31: =E31*F31 -> 0 | H31: 5000 | I31: =E31*F31+H31 -> 5000 | L31: PAGADO | M31: =IF(L31="Pagado", I31, 0) -> 5000 | P31: =IF(L31="NO APLICA",0, (I31-M31)) -> 0
A32: 31 | B32: =Usuarios!B32 & " " & Usuarios!C32 & " " & Usuarios!D32 -> Patricia Carcamo Gonzales | C32: 90 | D32: 113 | E32: =D32-C32 -> 23 | F32: 1182.6 | G32: =E32*F32 -> 27199.8 | H32: 5000 | I32: =E32*F32+H32 -> 32199.8 | L32: PAGADO | M32: =IF(L32="Pagado", I32, 0) -> 32199.8 | P32: =IF(L32="NO APLICA",0, (I32-M32)) -> 0
A33: 32 | B33: =Usuarios!B33 & " " & Usuarios!C33 & " " & Usuarios!D33 -> Natividad Soto | C33: 59 | D33: 66 | E33: =D33-C33 -> 7 | F33: 1182.6 | G33: =E33*F33 -> 8278.2 | H33: 5000 | I33: =E33*F33+H33 -> 13278.2 | L33: PAGADO | M33: =IF(L33="Pagado", I33, 0) -> 13278.2 | P33: =IF(L33="NO APLICA",0, (I33-M33)) -> 0
A34: 33 | B34: =Usuarios!B34 & " " & Usuarios!C34 & " " & Usuarios!D34 -> Maria Oliva Soto Almonacid | C34: 41 | D34: 43 | E34: =D34-C34 -> 2 | F34: 1182.6 | G34: =E34*F34 -> 2365.2 | H34: 5000 | I34: =E34*F34+H34 -> 7365.2 | L34: PAGADO | M34: =IF(L34="Pagado", I34, 0) -> 7365.2 | P34: =IF(L34="NO APLICA",0, (I34-M34)) -> 0
... A43: 42 | B43: =Usuarios!B43 & " " & Usuarios!C43 & " " & Usuarios!D43 -> Leo Soto | C43: 0 | D43: 0 | E43: =D43-C43 -> 0 | F43: 1182.6 | G43: =E43*F43 -> 0 | H43: 5000 | I43: =E43*F43+H43 -> 5000 | L43: PENDIENTE | M43: =IF(L43="Pagado", I43, 0) -> 0 | P43: =IF(L43="NO APLICA",0, (I43-M43)) -> 5000
A44: 43 | B44: =Usuarios!B44 & " " & Usuarios!C44 & " " & Usuarios!D44 -> Ramon Maldonado | C44: 0 | D44: 0 | E44: =D44-C44 -> 0 | F44: 1182.6 | G44: =E44*F44 -> 0 | H44: 5000 | I44: =E44*F44+H44 -> 5000 | L44: PENDIENTE | M44: =IF(L44="Pagado", I44, 0) -> 0 | O44: TRANSFERENCIA | P44: =IF(L44="NO APLICA",0, (I44-M44)) -> 5000
A45: 44 | B45: =Usuarios!B45 & " " & Usuarios!C45 & " " & Usuarios!D45 -> María Sonia Quintui | C45: 0 | D45: 0 | E45: =D45-C45 -> 0 | F45: 1182.6 | G45: =E45*F45 -> 0 | H45: 5000 | I45: =E45*F45+H45 -> 5000 | L45: PAGADO | M45: =IF(L45="Pagado", I45, 0) -> 5000 | P45: =IF(L45="NO APLICA",0, (I45-M45)) -> 0
A46: 45 | B46: =Usuarios!B46 & " " & Usuarios!C46 & " " & Usuarios!D46 -> Monica Cuello | C46: 0 | D46: 0 | E46: =D46-C46 -> 0 | F46: 1182.6 | G46: =E46*F46 -> 0 | H46: 5000 | I46: =E46*F46+H46 -> 5000 | L46: PAGADO | M46: =IF(L46="Pagado", I46, 0) -> 5000 | P46: =IF(L46="NO APLICA",0, (I46-M46)) -> 0
A47: 46 | B47: =Usuarios!B47 & " " & Usuarios!C47 & " " & Usuarios!D47 -> Mauricio Muñoz taller | C47: 0 | D47: 0 | E47: =D47-C47 -> 0 | F47: 1182.6 | G47: =E47*F47 -> 0 | H47: 5000 | I47: =E47*F47+H47 -> 5000 | L47: PENDIENTE | M47: =IF(L47="Pagado", I47, 0) -> 0 | P47: =IF(L47="NO APLICA",0, (I47-M47)) -> 5000
A48: 47 | B48: =Usuarios!B48 & " " & Usuarios!C48 & " " & Usuarios!D48 -> Pablo Contreras | C48: 0 | D48: 0 | E48: =D48-C48 -> 0 | F48: 1182.6 | G48: =E48*F48 -> 0 | H48: 5000 | I48: =E48*F48+H48 -> 5000 | L48: PAGADO | M48: =IF(L48="Pagado", I48, 0) -> 5000 | P48: =IF(L48="NO APLICA",0, (I48-M48)) -> 0
A49: 48 | B49: =Usuarios!B49 & " " & Usuarios!C49 & " " & Usuarios!D49 -> Luis Vicente Mondaca Muñoz | C49: 196 | D49: 226 | E49: =D49-C49 -> 30 | F49: 1182.6 | G49: =E49*F49 -> 35478 | H49: 5000 | I49: =E49*F49+H49 -> 40478 | L49: PAGADO | M49: =IF(L49="Pagado", I49, 0) -> 40478 | P49: =IF(L49="NO APLICA",0, (I49-M49)) -> 0
A50: 49 | B50: =Usuarios!B50 & " " & Usuarios!C50 & " " & Usuarios!D50 -> Rosa Nuñez | C50: 65 | D50: 70 | E50: =D50-C50 -> 5 | F50: 1182.6 | G50: =E50*F50 -> 5913 | H50: 5000 | I50: =E50*F50+H50 -> 10913 | L50: PAGADO | M50: =IF(L50="Pagado", I50, 0) -> 10913 | P50: =IF(L50="NO APLICA",0, (I50-M50)) -> 0
A51: 50 | B51: =Usuarios!B51 & " " & Usuarios!C51 & " " & Usuarios!D51 -> Gloria Isamar Velasquez Almonacid | C51: 11 | D51: 18 | E51: =D51-C51 -> 7 | F51: 1182.6 | G51: =E51*F51 -> 8278.2 | H51: 5000 | I51: =E51*F51+H51 -> 13278.2 | L51: PAGADO | M51: =IF(L51="Pagado", I51, 0) -> 13278.2 | P51: =IF(L51="NO APLICA",0, (I51-M51)) -> 0
A52: 51 | B52: =Usuarios!B52 & " " & Usuarios!C52 & " " & Usuarios!D52 -> Maria Manquian | C52: 0 | D52: 0 | E52: =D52-C52 -> 0 | F52: 1182.6 | G52: =E52*F52 -> 0 | H52: 5000 | I52: =E52*F52+H52 -> 5000 | L52: PAGADO | M52: =IF(L52="Pagado", I52, 0) -> 5000 | O52: TRANSFERENCIA | P52: =IF(L52="NO APLICA",0, (I52-M52)) -> 0
A53: 52 | B53: =Usuarios!B53 & " " & Usuarios!C53 & " " & Usuarios!D53 -> Esteban Oyarzo Levil | C53: 0 | D53: 0 | E53: =D53-C53 -> 0 | F53: 1182.6 | G53: =E53*F53 -> 0 | H53: 5000 | I53: =E53*F53+H53 -> 5000 | L53: PAGADO | M53: =IF(L53="Pagado", I53, 0) -> 5000 | P53: =IF(L53="NO APLICA",0, (I53-M53)) -> 0
A54: 53 | B54: =Usuarios!B54 & " " & Usuarios!C54 & " " & Usuarios!D54 -> Nicolas Andres Cardenas Bustamante | C54: 0 | D54: 0 | E54: =D54-C54 -> 0 | F54: 1182.6 | G54: =E54*F54 -> 0 | H54: 5000 | I54: =E54*F54+H54 -> 5000 | L54: PAGADO | M54: =IF(L54="Pagado", I54, 0) -> 5000 | P54: =IF(L54="NO APLICA",0, (I54-M54)) -> 0
A55: 54 | B55: =Usuarios!B55 & " " & Usuarios!C55 & " " & Usuarios!D55 -> Rosa Mancilla | C55: 0 | D55: 106 | E55: =D55-C55 -> 106 | F55: 1182.6 | G55: =E55*F55 -> 125355.6 | H55: 5000 | I55: =E55*F55+H55 -> 130355.6 | L55: PAGADO | M55: =IF(L55="Pagado", I55, 0) -> 130355.6 | P55: =IF(L55="NO APLICA",0, (I55-M55)) -> 0
...

Sheet 02-2025
A1: ID | B1: Nombre | C1: Lectura_Anterior | D1: Lectura_Actual | E1: Consumo_m3 | F1: Tarifa_m3 | G1: Subtotal_Consumo | H1: Cargo_Fijo | I1: Total_Factura | J1: Fecha_Lectura | K1: Periodo | L1: Estado_Pago | M1: Monto_Pagado | N1: Fecha_Pago | O1: Forma_Pago | P1: Saldo_Pendiente | Q1: comprobante_link
A2: 41 | B2: =Usuarios!B42 & " " & Usuarios!C42 & " " & Usuarios!D42 -> Astrid Gomez | C2: {=INDEX(INDIRECT("'" & TEXT(EDATE(J2,-2),"mm-yyyy") & "'!D:D"), MATCH(A2,INDIRECT("'" & TEXT(EDATE(J2,-2),"mm-yyyy") & "'!A:A"),0))} -> 86 | D2: 91 | E2: =D2-C2 -> 5 | F2: 1182.6 | G2: =E2*F2 -> 5913 | H2: 5000 | I2: =E2*F2+H2 -> 10913 | J2: 45724 | L2: PENDIENTE | M2: =IF(L2="Pagado", I2, 0) -> 0 | P2: =IF(L2="NO APLICA",0, (I2-M2)) -> 10913
A3: 16 | B3: =Usuarios!B17 & " " & Usuarios!C17 & " " & Usuarios!D17 -> Carlos Agüero | C3: {=INDEX('01-2025'!D:D,MATCH(INDEX(A:A, ROW()), '01-2025'!A:A, 0))} -> 150 | D3: 161 | E3: =D3-C3 -> 11 | F3: 1182.6 | G3: =E3*F3 -> 13008.6 | H3: 5000 | I3: =E3*F3+H3 -> 18008.6 | J3: 45724 | L3: PAGADO | M3: =IF(L3="Pagado", I3, 0) -> 18008.6 | P3: =IF(L3="NO APLICA",0, (I3-M3)) -> 0
A4: 13 | B4: =Usuarios!B14 & " " & Usuarios!C14 & " " & Usuarios!D14 -> Carlos Gamin | C4: {=INDEX('01-2025'!D:D,MATCH(INDEX(A:A, ROW()), '01-2025'!A:A, 0))} -> 158 | D4: 171 | E4: =D4-C4 -> 13 | F4: 1182.6 | G4: =E4*F4 -> 15373.8 | H4: 5000 | I4: =E4*F4+H4 -> 20373.8 | J4: 45724 | L4: PENDIENTE | M4: =IF(L4="Pagado", I4, 0) -> 0 | P4: =IF(L4="NO APLICA",0, (I4-M4)) -> 20373.8
A5: 23 | B5: =Usuarios!B24 & " " & Usuarios!C24 & " " & Usuarios!D24 -> Carlos Nahuelpan | C5: {=INDEX('01-2025'!D:D,MATCH(INDEX(A:A, ROW()), '01-2025'!A:A, 0))} -> 92 | D5: 100 | E5: =D5-C5 -> 8 | F5: 1182.6 | G5: =E5*F5 -> 9460.8 | H5: 5000 | I5: =E5*F5+H5 -> 14460.8 | J5: 45724 | L5: PAGADO | M5: =IF(L5="Pagado", I5, 0) -> 14460.8 | P5: =IF(L5="NO APLICA",0, (I5-M5)) -> 0
A6: 4 | B6: =Usuarios!B5 & " " & Usuarios!C5 & " " & Usuarios!D5 -> Cristian Oyarzo | C6: {=INDEX('01-2025'!D:D,MATCH(INDEX(A:A, ROW()), '01-2025'!A:A, 0))} -> 420 | D6: 455 | E6: =D6-C6 -> 35 | F6: 1182.6 | G6: =E6*F6 -> 41391 | H6: 5000 | I6: =E6*F6+H6 -> 46391 | J6: 45724 | L6: PAGADO | M6: =IF(L6="Pagado", I6, 0) -> 46391 | P6: =IF(L6="NO APLICA",0, (I6-M6)) -> 0
A7: 36 | B7: =Usuarios!B37 & " " & Usuarios!C37 & " " & Usuarios!D37 -> Danilo Soto Soto | C7: {=INDEX('01-2025'!D:D,MATCH(INDEX(A:A, ROW()), '01-2025'!A:A, 0))} -> 2 | D7: 2 | E7: =D7-C7 -> 0 | F7: 1182.6 | G7: =E7*F7 -> 0 | H7: 5000 | I7: =E7*F7+H7 -> 5000 | J7: 45724 | L7: PENDIENTE | M7: =IF(L7="Pagado", I7, 0) -> 0 | P7: =IF(L7="NO APLICA",0, (I7-M7)) -> 5000
A8: 10 | B8: =Usuarios!B11 & " " & Usuarios!C11 & " " & Usuarios!D11 -> David Cartes | C8: {=INDEX('01-2025'!D:D,MATCH(INDEX(A:A, ROW()), '01-2025'!A:A, 0))} -> 97 | D8: 104 | E8: =D8-C8 -> 7 | F8: 1182.6 | G8: =E8*F8 -> 8278.2 | H8: 5000 | I8: =E8*F8+H8 -> 13278.2 | J8: 45724 | L8: PAGADO | M8: =IF(L8="Pagado", I8, 0) -> 13278.2 | P8: =IF(L8="NO APLICA",0, (I8-M8)) -> 0
A9: 19 | B9: =Usuarios!B20 & " " & Usuarios!C20 & " " & Usuarios!D20 -> Eduardo Chavez | C9: {=INDEX('01-2025'!D:D,MATCH(INDEX(A:A, ROW()), '01-2025'!A:A, 0))} -> 67 | D9: 73 | E9: =D9-C9 -> 6 | F9: 1182.6 | G9: =E9*F9 -> 7095.6 | H9: 5000 | I9: =E9*F9+H9 -> 12095.6 | J9: 45724 | L9: PAGADO | M9: =IF(L9="Pagado", I9, 0) -> 12095.6 | P9: =IF(L9="NO APLICA",0, (I9-M9)) -> 0
A10: 52 | B10: =Usuarios!B53 & " " & Usuarios!C53 & " " & Usuarios!D53 -> Esteban Oyarzo Levil | C10: {=INDEX('01-2025'!D:D,MATCH(INDEX(A:A, ROW()), '01-2025'!A:A, 0))} -> 0 | D10: 0 | E10: =D10-C10 -> 0 | F10: 1182.6 | G10: =E10*F10 -> 0 | H10: 5000 | I10: =E10*F10+H10 -> 5000 | J10: 45724 | L10: PENDIENTE | M10: =IF(L10="Pagado", I10, 0) -> 0 | P10: =IF(L10="NO APLICA",0, (I10-M10)) -> 5000
A11: 8 | B11: =Usuarios!B9 & " " & Usuarios!C9 & " " & Usuarios!D9 -> Gabriel Farias | C11: {=INDEX('01-2025'!D:D,MATCH(INDEX(A:A, ROW()), '01-2025'!A:A, 0))} -> 379 | D11: 399 | E11: =D11-C11 -> 20 | F11: 1182.6 | G11: =E11*F11 -> 23652 | H11: 5000 | I11: =E11*F11+H11 -> 28652 | J11: 45724 | L11: PAGADO | M11: =IF(L11="Pagado", I11, 0) -> 28652 | P11: =IF(L11="NO APLICA",0, (I11-M11)) -> 0
A12: 2 | B12: =Usuarios!B3 & " " & Usuarios!C3 & " " & Usuarios!D3 -> Gabriel Barria Zuñiga | C12: {=INDEX('01-2025'!D:D,MATCH(INDEX(A:A, ROW()), '01-2025'!A:A, 0))} -> 253 | D12: 270 | E12: =D12-C12 -> 17 | F12: 1182.6 | G12: =E12*F12 -> 20104.2 | H12: 5000 | I12: =E12*F12+H12 -> 25104.2 | J12: 45724 | L12: PAGADO | M12: =IF(L12="Pagado", I12, 0) -> 25104.2 | P12: =IF(L12="NO APLICA",0, (I12-M12)) -> 0
A13: 3 | B13: =Usuarios!B4 & " " & Usuarios!C4 & " " & Usuarios!D4 -> Gino Reyes | C13: {=INDEX('01-2025'!D:D,MATCH(INDEX(A:A, ROW()), '01-2025'!A:A, 0))} -> 55 | D13: 60 | E13: =D13-C13 -> 5 | F13: 1182.6 | G13: =E13*F13 -> 5913 | H13: 5000 | I13: =E13*F13+H13 -> 10913 | J13: 45724 | L13: PAGADO | M13: =IF(L13="Pagado", I13, 0) -> 10913 | P13: =IF(L13="NO APLICA",0, (I13-M13)) -> 0
A14: 39 | B14: =Usuarios!B40 & " " & Usuarios!C40 & " " & Usuarios!D40 -> Gloria Alvarez | C14: {=INDEX('01-2025'!D:D,MATCH(INDEX(A:A, ROW()), '01-2025'!A:A, 0))} -> 108 | D14: 108 | E14: =D14-C14 -> 0 | F14: 1182.6 | G14: =E14*F14 -> 0 | H14: 5000 | I14: =E14*F14+H14 -> 5000 | J14: 45724 | L14: PAGADO | M14: =IF(L14="Pagado", I14, 0) -> 5000 | P14: =IF(L14="NO APLICA",0, (I14-M14)) -> 0
A15: 40 | B15: =Usuarios!B41 & " " & Usuarios!C41 & " " & Usuarios!D41 -> Gloria Levil | C15: {=INDEX('01-2025'!D:D,MATCH(INDEX(A:A, ROW()), '01-2025'!A:A, 0))} -> 81 | D15: 85 | E15: =D15-C15 -> 4 | F15: 1182.6 | G15: =E15*F15 -> 4730.4 | H15: 5000 | I15: =E15*F15+H15 -> 9730.4 | J15: 45724 | L15: PENDIENTE | M15: =IF(L15="Pagado", I15, 0) -> 0 | P15: =IF(L15="NO APLICA",0, (I15-M15)) -> 9730.4
A16: 50 | B16: =Usuarios!B51 & " " & Usuarios!C51 & " " & Usuarios!D51 -> Gloria Isamar Velasquez Almonacid | C16: {=INDEX('01-2025'!D:D,MATCH(INDEX(A:A, ROW()), '01-2025'!A:A, 0))} -> 18 | D16: 24 | E16: =D16-C16 -> 6 | F16: 1182.6 | G16: =E16*F16 -> 7095.6 | H16: 5000 | I16: =E16*F16+H16 -> 12095.6 | J16: 45724 | L16: PAGADO | M16: =IF(L16="Pagado", I16, 0) -> 12095.6 | P16: =IF(L16="NO APLICA",0, (I16-M16)) -> 0
A17: 26 | B17: =Usuarios!B27 & " " & Usuarios!C27 & " " & Usuarios!D27 -> Guido Quintuy | C17: {=INDEX('01-2025'!D:D,MATCH(INDEX(A:A, ROW()), '01-2025'!A:A, 0))} -> 117 | D17: 128 | E17: =D17-C17 -> 11 | F17: 1182.6 | G17: =E17*F17 -> 13008.6 | H17: 5000 | I17: =E17*F17+H17 -> 18008.6 | J17: 45724 | L17: PAGADO | M17: =IF(L17="Pagado", I17, 0) -> 18008.6 | P17: =IF(L17="NO APLICA",0, (I17-M17)) -> 0
A18: 55 | B18: =Usuarios!B56 & " " & Usuarios!C56 & " " & Usuarios!D56 -> Guido Quintuy - Sitio vacío | C18: {=INDEX('01-2025'!D:D,MATCH(INDEX(A:A, ROW()), '01-2025'!A:A, 0))} -> 0 | D18: 0 | E18: =D18-C18 -> 0 | F18: 1182.6 | G18: =E18*F18 -> 0 | H18: 5000 | I18: =E18*F18+H18 -> 5000 | J18: 45724 | L18: PENDIENTE | M18: =IF(L18="Pagado", I18, 0) -> 0 | P18: =IF(L18="NO APLICA",0, (I18-M18)) -> 5000
A19: 25 | B19: =Usuarios!B26 & " " & Usuarios!C26 & " " & Usuarios!D26 -> Inés Velasquez | C19: {=INDEX('01-2025'!D:D,MATCH(INDEX(A:A, ROW()), '01-2025'!A:A, 0))} -> 100 | D19: 109 | E19: =D19-C19 -> 9 | F19: 1182.6 | G19: =E19*F19 -> 10643.4 | H19: 5000 | I19: =E19*F19+H19 -> 15643.4 | J19: 45724 | L19: PAGADO | M19: =IF(L19="Pagado", I19, 0) -> 15643.4 | P19: =IF(L19="NO APLICA",0, (I19-M19)) -> 0
A20: 17 | B20: =Usuarios!B18 & " " & Usuarios!C18 & " " & Usuarios!D18 -> Joaquin Claramunt | C20: {=INDEX('01-2025'!D:D,MATCH(INDEX(A:A, ROW()), '01-2025'!A:A, 0))} -> 145 | D20: 152 | E20: =D20-C20 -> 7 | F20: 1182.6 | G20: =E20*F20 -> 8278.2 | H20: 5000 | I20: =E20*F20+H20 -> 13278.2 | J20: 45724 | L20: PAGADO | M20: =IF(L20="Pagado", I20, 0) -> 13278.2 | P20: =IF(L20="NO APLICA",0, (I20-M20)) -> 0
A21: 35 | B21: =Usuarios!B36 & " " & Usuarios!C36 & " " & Usuarios!D36 -> José Paredes | C21: {=INDEX('01-2025'!D:D,MATCH(INDEX(A:A, ROW()), '01-2025'!A:A, 0))} -> 0 | D21: 0 | E21: =D21-C21 -> 0 | F21: 1182.6 | G21: =E21*F21 -> 0 | H21: 5000 | I21: =E21*F21+H21 -> 5000 | J21: 45724 | L21: PENDIENTE | M21: =IF(L21="Pagado", I21, 0) -> 0 | P21: =IF(L21="NO APLICA",0, (I21-M21)) -> 5000
A22: 20 | B22: =Usuarios!B21 & " " & Usuarios!C21 & " " & Usuarios!D21 -> Juan Chavez | C22: {=INDEX('01-2025'!D:D,MATCH(INDEX(A:A, ROW()), '01-2025'!A:A, 0))} -> 21 | D22: 22 | E22: =D22-C22 -> 1 | F22: 1182.6 | G22: =E22*F22 -> 1182.6 | H22: 5000 | I22: =E22*F22+H22 -> 6182.6 | J22: 45724 | L22: PAGADO | M22: =IF(L22="Pagado", I22, 0) -> 6182.6 | P22: =IF(L22="NO APLICA",0, (I22-M22)) -> 0
A23: 42 | B23: =Usuarios!B43 & " " & Usuarios!C43 & " " & Usuarios!D43 -> Leo Soto | C23: {=INDEX('01-2025'!D:D,MATCH(INDEX(A:A, ROW()), '01-2025'!A:A, 0))} -> 0 | D23: 0 | E23: =D23-C23 -> 0 | F23: 1182.6 | G23: =E23*F23 -> 0 | H23: 5000 | I23: =E23*F23+H23 -> 5000 | J23: 45724 | L23: PENDIENTE | M23: =IF(L23="Pagado", I23, 0) -> 0 | P23: =IF(L23="NO APLICA",0, (I23-M23)) -> 5000
A24: 57 | B24: =Usuarios!B58 & " " & Usuarios!C58 & " " & Usuarios!D58 -> Lishby Fuentes Diaz | C24: {=INDEX('01-2025'!D:D,MATCH(INDEX(A:A, ROW()), '01-2025'!A:A, 0))} -> 0 | D24: 0 | E24: =D24-C24 -> 0 | F24: 1182.6 | G24: =E24*F24 -> 0 | H24: 5000 | I24: =E24*F24+H24 -> 5000 | J24: 45724 | L24: NO APLICA | M24: =IF(L24="Pagado", I24, 0) -> 0 | P24: =IF(L24="NO APLICA",0, (I24-M24)) -> 0
A25: 48 | B25: =Usuarios!B49 & " " & Usuarios!C49 & " " & Usuarios!D49 -> Luis Vicente Mondaca Muñoz | C25: {=INDEX('01-2025'!D:D,MATCH(INDEX(A:A, ROW()), '01-2025'!A:A, 0))} -> 226 | D25: 249 | E25: =D25-C25 -> 23 | F25: 1182.6 | G25: =E25*F25 -> 27199.8 | H25: 5000 | I25: =E25*F25+H25 -> 32199.8 | J25: 45724 | L25: PAGADO | M25: =IF(L25="Pagado", I25, 0) -> 32199.8 | P25: =IF(L25="NO APLICA",0, (I25-M25)) -> 0
A26: 30 | B26: =Usuarios!B31 & " " & Usuarios!C31 & " " & Usuarios!D31 -> Luz Maldonado | C26: {=INDEX('01-2025'!D:D,MATCH(INDEX(A:A, ROW()), '01-2025'!A:A, 0))} -> 5 | D26: 5 | E26: =D26-C26 -> 0 | F26: 1182.6 | G26: =E26*F26 -> 0 | H26: 5000 | I26: =E26*F26+H26 -> 5000 | J26: 45724 | L26: PAGADO | M26: =IF(L26="Pagado", I26, 0) -> 5000 | P26: =IF(L26="NO APLICA",0, (I26-M26)) -> 0
A27: 7 | B27: =Usuarios!B8 & " " & Usuarios!C8 & " " & Usuarios!D8 -> Marcelo Millanao | C27: {=INDEX('01-2025'!D:D,MATCH(INDEX(A:A, ROW()), '01-2025'!A:A, 0))} -> 211 | D27: 224 | E27: =D27-C27 -> 13 | F27: 1182.6 | G27: =E27*F27 -> 15373.8 | H27: 5000 | I27: =E27*F27+H27 -> 20373.8 | J27: 45724 | L27: PAGADO | M27: =IF(L27="Pagado", I27, 0) -> 20373.8 | P27: =IF(L27="NO APLICA",0, (I27-M27)) -> 0
A28: 51 | B28: =Usuarios!B52 & " " & Usuarios!C52 & " " & Usuarios!D52 -> Maria Manquian | C28: {=INDEX('01-2025'!D:D,MATCH(INDEX(A:A, ROW()), '01-2025'!A:A, 0))} -> 0 | D28: 0 | E28: =D28-C28 -> 0 | F28: 1182.6 | G28: =E28*F28 -> 0 | H28: 5000 | I28: =E28*F28+H28 -> 5000 | J28: 45724 | L28: PAGADO | M28: =IF(L28="Pagado", I28, 0) -> 5000 | O28: TRANSFERENCIA | P28: =IF(L28="NO APLICA",0, (I28-M28)) -> 0
A29: 9 | B29: =Usuarios!B10 & " " & Usuarios!C10 & " " & Usuarios!D10 -> Maria Marin | C29: {=INDEX('01-2025'!D:D,MATCH(INDEX(A:A, ROW()), '01-2025'!A:A, 0))} -> 137 | D29: 153 | E29: =D29-C29 -> 16 | F29: 1182.6 | G29: =E29*F29 -> 18921.6 | H29: 5000 | I29: =E29*F29+H29 -> 23921.6 | J29: 45724 | L29: PAGADO | M29: =IF(L29="Pagado", I29, 0) -> 23921.6 | P29: =IF(L29="NO APLICA",0, (I29-M29)) -> 0
A30: 33 | B30: =Usuarios!B34 & " " & Usuarios!C34 & " " & Usuarios!D34 -> Maria Oliva Soto Almonacid | C30: {=INDEX('01-2025'!D:D,MATCH(INDEX(A:A, ROW()), '01-2025'!A:A, 0))} -> 43 | D30: 45 | E30: =D30-C30 -> 2 | F30: 1182.6 | G30: =E30*F30 -> 2365.2 | H30: 5000 | I30: =E30*F30+H30 -> 7365.2 | J30: 45724 | L30: PAGADO | M30: =IF(L30="Pagado", I30, 0) -> 7365.2 | P30: =IF(L30="NO APLICA",0, (I30-M30)) -> 0
A31: 44 | B31: =Usuarios!B45 & " " & Usuarios!C45 & " " & Usuarios!D45 -> María Sonia Quintui | C31: {=INDEX('01-2025'!D:D,MATCH(INDEX(A:A, ROW()), '01-2025'!A:A, 0))} -> 0 | D31: 0 | E31: =D31-C31 -> 0 | F31: 1182.6 | G31: =E31*F31 -> 0 | H31: 5000 | I31: =E31*F31+H31 -> 5000 | J31: 45724 | L31: PAGADO | M31: =IF(L31="Pagado", I31, 0) -> 5000 | P31: =IF(L31="NO APLICA",0, (I31-M31)) -> 0
A32: 24 | B32: =Usuarios!B25 & " " & Usuarios!C25 & " " & Usuarios!D25 -> Maria Velasquez Miranda | C32: {=INDEX('01-2025'!D:D,MATCH(INDEX(A:A, ROW()), '01-2025'!A:A, 0))} -> 203 | D32: 227 | E32: =D32-C32 -> 24 | F32: 1182.6 | G32: =E32*F32 -> 28382.4 | H32: 5000 | I32: =E32*F32+H32 -> 33382.4 | J32: 45724 | L32: PAGADO | M32: =IF(L32="Pagado", I32, 0) -> 33382.4 | P32: =IF(L32="NO APLICA",0, (I32-M32)) -> 0
A33: 56 | B33: =Usuarios!B57 & " " & Usuarios!C57 & " " & Usuarios!D57 -> Mario Velasquez | C33: {=INDEX('01-2025'!D:D,MATCH(INDEX(A:A, ROW()), '01-2025'!A:A, 0))} -> 5 | D33: 8 | E33: =D33-C33 -> 3 | F33: 1182.6 | G33: =E33*F33 -> 3547.8 | H33: 5000 | I33: =E33*F33+H33 -> 8547.8 | J33: 45724 | L33: PENDIENTE | M33: =IF(L33="Pagado", I33, 0) -> 0 | P33: =IF(L33="NO APLICA",0, (I33-M33)) -> 8547.8
A34: 5 | B34: =Usuarios!B6 & " " & Usuarios!C6 & " " & Usuarios!D6 -> Marisol Castro | C34: {=INDEX('01-2025'!D:D,MATCH(INDEX(A:A, ROW()), '01-2025'!A:A, 0))} -> 88 | D34: 96 | E34: =D34-C34 -> 8 | F34: 1182.6 | G34: =E34*F34 -> 9460.8 | H34: 5000 | I34: =E34*F34+H34 -> 14460.8 | J34: 45724 | L34: PAGADO | M34: =IF(L34="Pagado", I34, 0) -> 14460.8 | P34: =IF(L34="NO APLICA",0, (I34-M34)) -> 0
A35: 6 | B35: =Usuarios!B7 & " " & Usuarios!C7 & " " & Usuarios!D7 -> Mauricio Muñoz | C35: {=INDEX('01-2025'!D:D,MATCH(INDEX(A:A, ROW()), '01-2025'!A:A, 0))} -> 174 | D35: 188 | E35: =D35-C35 -> 14 | F35: 1182.6 | G35: =E35*F35 -> 16556.4 | H35: 5000 | I35: =E35*F35+H35 -> 21556.4 | J35: 45724 | L35: PAGADO | M35: =IF(L35="Pagado", I35, 0) -> 21556.4 | P35: =IF(L35="NO APLICA",0, (I35-M35)) -> 0
A36: 46 | B36: =Usuarios!B47 & " " & Usuarios!C47 & " " & Usuarios!D47 -> Mauricio Muñoz taller | C36: {=INDEX('01-2025'!D:D,MATCH(INDEX(A:A, ROW()), '01-2025'!A:A, 0))} -> 0 | D36: 0 | E36: =D36-C36 -> 0 | F36: 1182.6 | G36: =E36*F36 -> 0 | H36: 5000 | I36: =E36*F36+H36 -> 5000 | J36: 45724 | L36: PAGADO | M36: =IF(L36="Pagado", I36, 0) -> 5000 | P36: =IF(L36="NO APLICA",0, (I36-M36)) -> 0
A37: 11 | B37: =Usuarios!B12 & " " & Usuarios!C12 & " " & Usuarios!D12 -> Miguel Ñanco | C37: {=INDEX('01-2025'!D:D,MATCH(INDEX(A:A, ROW()), '01-2025'!A:A, 0))} -> 189 | D37: 216 | E37: =D37-C37 -> 27 | F37: 1182.6 | G37: =E37*F37 -> 31930.2 | H37: 5000 | I37: =E37*F37+H37 -> 36930.2 | J37: 45724 | L37: PAGADO | M37: =IF(L37="Pagado", I37, 0) -> 36930.2 | P37: =IF(L37="NO APLICA",0, (I37-M37)) -> 0
A38: 29 | B38: =Usuarios!B30 & " " & Usuarios!C30 & " " & Usuarios!D30 -> Miriam Alvarado | C38: {=INDEX('01-2025'!D:D,MATCH(INDEX(A:A, ROW()), '01-2025'!A:A, 0))} -> 515 | D38: 539 | E38: =D38-C38 -> 24 | F38: 1182.6 | G38: =E38*F38 -> 28382.4 | H38: 5000 | I38: =E38*F38+H38 -> 33382.4 | J38: 45724 | L38: PAGADO | M38: =IF(L38="Pagado", I38, 0) -> 33382.4 | P38: =IF(L38="NO APLICA",0, (I38-M38)) -> 0
A39: 45 | B39: =Usuarios!B46 & " " & Usuarios!C46 & " " & Usuarios!D46 -> Monica Cuello | C39: {=INDEX('01-2025'!D:D,MATCH(INDEX(A:A, ROW()), '01-2025'!A:A, 0))} -> 0 | D39: 0 | E39: =D39-C39 -> 0 | F39: 1182.6 | G39: =E39*F39 -> 0 | H39: 5000 | I39: =E39*F39+H39 -> 5000 | J39: 45724 | L39: PAGADO | M39: =IF(L39="Pagado", I39, 0) -> 5000 | P39: =IF(L39="NO APLICA",0, (I39-M39)) -> 0
A40: 1 | B40: =Usuarios!B2 & " " & Usuarios!C2 & " " & Usuarios!D2 -> Nancy Zuñiga Villarroel | C40: {=INDEX('01-2025'!D:D,MATCH(INDEX(A:A, ROW()), '01-2025'!A:A, 0))} -> 165 | D40: 179 | E40: =D40-C40 -> 14 | F40: 1182.6 | G40: =E40*F40 -> 16556.4 | H40: 5000 | I40: =E40*F40+H40 -> 21556.4 | J40: 45724 | L40: PAGADO | M40: =IF(L40="Pagado", I40, 0) -> 21556.4 | P40: =IF(L40="NO APLICA",0, (I40-M40)) -> 0
...

Sheet 03-2025
A1: ID | B1: Nombre | C1: Lectura_Anterior | D1: Lectura_Actual | E1: Consumo_m3 | F1: Tarifa_m3 | G1: Subtotal_Consumo | H1: Cargo_Fijo | I1: Total_Factura | J1: Fecha_Lectura | K1: Periodo | L1: Estado_Pago | M1: Monto_Pagado | N1: Fecha_Pago | O1: Forma_Pago | P1: Saldo_Pendiente | Q1: comprobante_link
A2: 1 | B2: =Usuarios!B2 & " " & Usuarios!C2 & " " & Usuarios!D2 -> Nancy Zuñiga Villarroel | C2: =INDEX(INDIRECT("'" & TEXT(EDATE(J2,-2),"mm-yyyy") & "'!D:D"), MATCH(A2,INDIRECT("'" & TEXT(EDATE(J2,-2),"mm-yyyy") & "'!A:A"),0)) -> 179 | D2: 193 | E2: =D2-C2 -> 14 | F2: 1182.6 | G2: =E2*F2 -> 16556.4 | H2: 5000 | I2: =E2*F2+H2 -> 21556.4 | J2: 45755 | L2: PAGADO | M2: =IF(L2="Pagado", I2, 0) -> 21556.4 | P2: =IF(L2="NO APLICA",0, (I2-M2)) -> 0
A3: 2 | B3: =Usuarios!B3 & " " & Usuarios!C3 & " " & Usuarios!D3 -> Gabriel Barria Zuñiga | C3: =INDEX(INDIRECT("'" & TEXT(EDATE(J3,-2),"mm-yyyy") & "'!D:D"), MATCH(A3,INDIRECT("'" & TEXT(EDATE(J3,-2),"mm-yyyy") & "'!A:A"),0)) -> 270 | D3: 292 | E3: =D3-C3 -> 22 | F3: 1182.6 | G3: =E3*F3 -> 26017.2 | H3: 5000 | I3: =E3*F3+H3 -> 31017.2 | J3: 45755 | L3: PAGADO | M3: =IF(L3="Pagado", I3, 0) -> 31017.2 | P3: =IF(L3="NO APLICA",0, (I3-M3)) -> 0
A4: 3 | B4: =Usuarios!B4 & " " & Usuarios!C4 & " " & Usuarios!D4 -> Gino Reyes | C4: =INDEX(INDIRECT("'" & TEXT(EDATE(J4,-2),"mm-yyyy") & "'!D:D"), MATCH(A4,INDIRECT("'" & TEXT(EDATE(J4,-2),"mm-yyyy") & "'!A:A"),0)) -> 60 | D4: 66 | E4: =D4-C4 -> 6 | F4: 1182.6 | G4: =E4*F4 -> 7095.6 | H4: 5000 | I4: =E4*F4+H4 -> 12095.6 | J4: 45755 | L4: PENDIENTE | M4: =IF(L4="Pagado", I4, 0) -> 0 | P4: =IF(L4="NO APLICA",0, (I4-M4)) -> 12095.6
A5: 4 | B5: =Usuarios!B5 & " " & Usuarios!C5 & " " & Usuarios!D5 -> Cristian Oyarzo | C5: =INDEX(INDIRECT("'" & TEXT(EDATE(J5,-2),"mm-yyyy") & "'!D:D"), MATCH(A5,INDIRECT("'" & TEXT(EDATE(J5,-2),"mm-yyyy") & "'!A:A"),0)) -> 455 | D5: 493 | E5: =D5-C5 -> 38 | F5: 1182.6 | G5: =E5*F5 -> 44938.8 | H5: 5000 | I5: =E5*F5+H5 -> 49938.8 | J5: 45755 | L5: PAGADO | M5: =IF(L5="Pagado", I5, 0) -> 49938.8 | P5: =IF(L5="NO APLICA",0, (I5-M5)) -> 0
A6: 5 | B6: =Usuarios!B6 & " " & Usuarios!C6 & " " & Usuarios!D6 -> Marisol Castro | C6: =INDEX(INDIRECT("'" & TEXT(EDATE(J6,-2),"mm-yyyy") & "'!D:D"), MATCH(A6,INDIRECT("'" & TEXT(EDATE(J6,-2),"mm-yyyy") & "'!A:A"),0)) -> 96 | D6: 105 | E6: =D6-C6 -> 9 | F6: 1182.6 | G6: =E6*F6 -> 10643.4 | H6: 5000 | I6: =E6*F6+H6 -> 15643.4 | J6: 45755 | L6: PAGADO | M6: =IF(L6="Pagado", I6, 0) -> 15643.4 | P6: =IF(L6="NO APLICA",0, (I6-M6)) -> 0
A7: 6 | B7: =Usuarios!B7 & " " & Usuarios!C7 & " " & Usuarios!D7 -> Mauricio Muñoz | C7: =INDEX(INDIRECT("'" & TEXT(EDATE(J7,-2),"mm-yyyy") & "'!D:D"), MATCH(A7,INDIRECT("'" & TEXT(EDATE(J7,-2),"mm-yyyy") & "'!A:A"),0)) -> 188 | D7: 198 | E7: =D7-C7 -> 10 | F7: 1182.6 | G7: =E7*F7 -> 11826 | H7: 5000 | I7: =E7*F7+H7 -> 16826 | J7: 45755 | L7: PAGADO | M7: =IF(L7="Pagado", I7, 0) -> 16826 | P7: =IF(L7="NO APLICA",0, (I7-M7)) -> 0
A8: 7 | B8: =Usuarios!B8 & " " & Usuarios!C8 & " " & Usuarios!D8 -> Marcelo Millanao | C8: =INDEX(INDIRECT("'" & TEXT(EDATE(J8,-2),"mm-yyyy") & "'!D:D"), MATCH(A8,INDIRECT("'" & TEXT(EDATE(J8,-2),"mm-yyyy") & "'!A:A"),0)) -> 224 | D8: 238 | E8: =D8-C8 -> 14 | F8: 1182.6 | G8: =E8*F8 -> 16556.4 | H8: 5000 | I8: =E8*F8+H8 -> 21556.4 | J8: 45755 | L8: PAGADO | M8: =IF(L8="Pagado", I8, 0) -> 21556.4 | P8: =IF(L8="NO APLICA",0, (I8-M8)) -> 0
A9: 8 | B9: =Usuarios!B9 & " " & Usuarios!C9 & " " & Usuarios!D9 -> Gabriel Farias | C9: =INDEX(INDIRECT("'" & TEXT(EDATE(J9,-2),"mm-yyyy") & "'!D:D"), MATCH(A9,INDIRECT("'" & TEXT(EDATE(J9,-2),"mm-yyyy") & "'!A:A"),0)) -> 399 | D9: 432 | E9: =D9-C9 -> 33 | F9: 1182.6 | G9: =E9*F9 -> 39025.8 | H9: 5000 | I9: =E9*F9+H9 -> 44025.8 | J9: 45755 | L9: PAGADO | M9: =IF(L9="Pagado", I9, 0) -> 44025.8 | P9: =IF(L9="NO APLICA",0, (I9-M9)) -> 0
A10: 9 | B10: =Usuarios!B10 & " " & Usuarios!C10 & " " & Usuarios!D10 -> Maria Marin | C10: =INDEX(INDIRECT("'" & TEXT(EDATE(J10,-2),"mm-yyyy") & "'!D:D"), MATCH(A10,INDIRECT("'" & TEXT(EDATE(J10,-2),"mm-yyyy") & "'!A:A"),0)) -> 153 | D10: 177 | E10: =D10-C10 -> 24 | F10: 1182.6 | G10: =E10*F10 -> 28382.4 | H10: 5000 | I10: =E10*F10+H10 -> 33382.4 | J10: 45755 | L10: PAGADO | M10: =IF(L10="Pagado", I10, 0) -> 33382.4 | P10: =IF(L10="NO APLICA",0, (I10-M10)) -> 0
A11: 10 | B11: =Usuarios!B11 & " " & Usuarios!C11 & " " & Usuarios!D11 -> David Cartes | C11: =INDEX(INDIRECT("'" & TEXT(EDATE(J11,-2),"mm-yyyy") & "'!D:D"), MATCH(A11,INDIRECT("'" & TEXT(EDATE(J11,-2),"mm-yyyy") & "'!A:A"),0)) -> 104 | D11: 112 | E11: =D11-C11 -> 8 | F11: 1182.6 | G11: =E11*F11 -> 9460.8 | H11: 5000 | I11: =E11*F11+H11 -> 14460.8 | J11: 45755 | L11: PAGADO | M11: =IF(L11="Pagado", I11, 0) -> 14460.8 | P11: =IF(L11="NO APLICA",0, (I11-M11)) -> 0
A12: 11 | B12: =Usuarios!B12 & " " & Usuarios!C12 & " " & Usuarios!D12 -> Miguel Ñanco | C12: =INDEX(INDIRECT("'" & TEXT(EDATE(J12,-2),"mm-yyyy") & "'!D:D"), MATCH(A12,INDIRECT("'" & TEXT(EDATE(J12,-2),"mm-yyyy") & "'!A:A"),0)) -> 216 | D12: 240 | E12: =D12-C12 -> 24 | F12: 1182.6 | G12: =E12*F12 -> 28382.4 | H12: 5000 | I12: =E12*F12+H12 -> 33382.4 | J12: 45755 | L12: PAGADO | M12: =IF(L12="Pagado", I12, 0) -> 33382.4 | P12: =IF(L12="NO APLICA",0, (I12-M12)) -> 0
A13: 12 | B13: =Usuarios!B13 & " " & Usuarios!C13 & " " & Usuarios!D13 -> Pedro Contreras | C13: =INDEX(INDIRECT("'" & TEXT(EDATE(J13,-2),"mm-yyyy") & "'!D:D"), MATCH(A13,INDIRECT("'" & TEXT(EDATE(J13,-2),"mm-yyyy") & "'!A:A"),0)) -> 103 | D13: 109 | E13: =D13-C13 -> 6 | F13: 1182.6 | G13: =E13*F13 -> 7095.6 | H13: 5000 | I13: =E13*F13+H13 -> 12095.6 | J13: 45755 | L13: PENDIENTE | M13: =IF(L13="Pagado", I13, 0) -> 0 | P13: =IF(L13="NO APLICA",0, (I13-M13)) -> 12095.6
... A43: 42 | B43: =Usuarios!B43 & " " & Usuarios!C43 & " " & Usuarios!D43 -> Leo Soto | C43: =INDEX(INDIRECT("'" & TEXT(EDATE(J43,-2),"mm-yyyy") & "'!D:D"), MATCH(A43,INDIRECT("'" & TEXT(EDATE(J43,-2),"mm-yyyy") & "'!A:A"),0)) -> 0 | D43: 10 | E43: =D43-C43 -> 10 | F43: 1182.6 | G43: =E43*F43 -> 11826 | H43: 5000 | I43: =E43*F43+H43 -> 16826 | J43: 45755 | L43: PENDIENTE | M43: =IF(L43="Pagado", I43, 0) -> 0 | P43: =IF(L43="NO APLICA",0, (I43-M43)) -> 16826
A44: 43 | B44: =Usuarios!B44 & " " & Usuarios!C44 & " " & Usuarios!D44 -> Ramon Maldonado | C44: =INDEX(INDIRECT("'" & TEXT(EDATE(J44,-2),"mm-yyyy") & "'!D:D"), MATCH(A44,INDIRECT("'" & TEXT(EDATE(J44,-2),"mm-yyyy") & "'!A:A"),0)) -> 0 | D44: 0 | E44: =D44-C44 -> 0 | F44: 1182.6 | G44: =E44*F44 -> 0 | H44: 5000 | I44: =E44*F44+H44 -> 5000 | J44: 45755 | L44: PAGADO | M44: =IF(L44="Pagado", I44, 0) -> 5000 | O44: TRANSFERENCIA | P44: =IF(L44="NO APLICA",0, (I44-M44)) -> 0
A45: 44 | B45: =Usuarios!B45 & " " & Usuarios!C45 & " " & Usuarios!D45 -> María Sonia Quintui | C45: =INDEX(INDIRECT("'" & TEXT(EDATE(J45,-2),"mm-yyyy") & "'!D:D"), MATCH(A45,INDIRECT("'" & TEXT(EDATE(J45,-2),"mm-yyyy") & "'!A:A"),0)) -> 0 | D45: 0 | E45: =D45-C45 -> 0 | F45: 1182.6 | G45: =E45*F45 -> 0 | H45: 5000 | I45: =E45*F45+H45 -> 5000 | J45: 45755 | L45: PAGADO | M45: =IF(L45="Pagado", I45, 0) -> 5000 | P45: =IF(L45="NO APLICA",0, (I45-M45)) -> 0
A46: 45 | B46: =Usuarios!B46 & " " & Usuarios!C46 & " " & Usuarios!D46 -> Monica Cuello | C46: =INDEX(INDIRECT("'" & TEXT(EDATE(J46,-2),"mm-yyyy") & "'!D:D"), MATCH(A46,INDIRECT("'" & TEXT(EDATE(J46,-2),"mm-yyyy") & "'!A:A"),0)) -> 0 | D46: 0 | E46: =D46-C46 -> 0 | F46: 1182.6 | G46: =E46*F46 -> 0 | H46: 5000 | I46: =E46*F46+H46 -> 5000 | J46: 45755 | L46: PENDIENTE | M46: =IF(L46="Pagado", I46, 0) -> 0 | P46: =IF(L46="NO APLICA",0, (I46-M46)) -> 5000
A47: 46 | B47: =Usuarios!B47 & " " & Usuarios!C47 & " " & Usuarios!D47 -> Mauricio Muñoz taller | C47: =INDEX(INDIRECT("'" & TEXT(EDATE(J47,-2),"mm-yyyy") & "'!D:D"), MATCH(A47,INDIRECT("'" & TEXT(EDATE(J47,-2),"mm-yyyy") & "'!A:A"),0)) -> 0 | D47: 0 | E47: =D47-C47 -> 0 | F47: 1182.6 | G47: =E47*F47 -> 0 | H47: 5000 | I47: =E47*F47+H47 -> 5000 | J47: 45755 | L47: PENDIENTE | M47: =IF(L47="Pagado", I47, 0) -> 0 | P47: =IF(L47="NO APLICA",0, (I47-M47)) -> 5000
A48: 47 | B48: =Usuarios!B48 & " " & Usuarios!C48 & " " & Usuarios!D48 -> Pablo Contreras | C48: =INDEX(INDIRECT("'" & TEXT(EDATE(J48,-2),"mm-yyyy") & "'!D:D"), MATCH(A48,INDIRECT("'" & TEXT(EDATE(J48,-2),"mm-yyyy") & "'!A:A"),0)) -> 0 | D48: 0 | E48: =D48-C48 -> 0 | F48: 1182.6 | G48: =E48*F48 -> 0 | H48: 5000 | I48: =E48*F48+H48 -> 5000 | J48: 45755 | L48: PAGADO | M48: =IF(L48="Pagado", I48, 0) -> 5000 | P48: =IF(L48="NO APLICA",0, (I48-M48)) -> 0
A49: 48 | B49: =Usuarios!B49 & " " & Usuarios!C49 & " " & Usuarios!D49 -> Luis Vicente Mondaca Muñoz | C49: =INDEX(INDIRECT("'" & TEXT(EDATE(J49,-2),"mm-yyyy") & "'!D:D"), MATCH(A49,INDIRECT("'" & TEXT(EDATE(J49,-2),"mm-yyyy") & "'!A:A"),0)) -> 249 | D49: 281 | E49: =D49-C49 -> 32 | F49: 1182.6 | G49: =E49*F49 -> 37843.2 | H49: 5000 | I49: =E49*F49+H49 -> 42843.2 | J49: 45755 | L49: PAGADO | M49: =IF(L49="Pagado", I49, 0) -> 42843.2 | P49: =IF(L49="NO APLICA",0, (I49-M49)) -> 0
A50: 49 | B50: =Usuarios!B50 & " " & Usuarios!C50 & " " & Usuarios!D50 -> Rosa Nuñez | C50: =INDEX(INDIRECT("'" & TEXT(EDATE(J50,-2),"mm-yyyy") & "'!D:D"), MATCH(A50,INDIRECT("'" & TEXT(EDATE(J50,-2),"mm-yyyy") & "'!A:A"),0)) -> 76 | D50: 80 | E50: =D50-C50 -> 4 | F50: 1182.6 | G50: =E50*F50 -> 4730.4 | H50: 5000 | I50: =E50*F50+H50 -> 9730.4 | J50: 45755 | L50: PENDIENTE | M50: =IF(L50="Pagado", I50, 0) -> 0 | P50: =IF(L50="NO APLICA",0, (I50-M50)) -> 9730.4
A51: 50 | B51: =Usuarios!B51 & " " & Usuarios!C51 & " " & Usuarios!D51 -> Gloria Isamar Velasquez Almonacid | C51: =INDEX(INDIRECT("'" & TEXT(EDATE(J51,-2),"mm-yyyy") & "'!D:D"), MATCH(A51,INDIRECT("'" & TEXT(EDATE(J51,-2),"mm-yyyy") & "'!A:A"),0)) -> 24 | D51: 35 | E51: =D51-C51 -> 11 | F51: 1182.6 | G51: =E51*F51 -> 13008.6 | H51: 5000 | I51: =E51*F51+H51 -> 18008.6 | J51: 45755 | L51: PENDIENTE | M51: =IF(L51="Pagado", I51, 0) -> 0 | P51: =IF(L51="NO APLICA",0, (I51-M51)) -> 18008.6
A52: 51 | B52: =Usuarios!B52 & " " & Usuarios!C52 & " " & Usuarios!D52 -> Maria Manquian | C52: =INDEX(INDIRECT("'" & TEXT(EDATE(J52,-2),"mm-yyyy") & "'!D:D"), MATCH(A52,INDIRECT("'" & TEXT(EDATE(J52,-2),"mm-yyyy") & "'!A:A"),0)) -> 0 | D52: 0 | E52: =D52-C52 -> 0 | F52: 1182.6 | G52: =E52*F52 -> 0 | H52: 5000 | I52: =E52*F52+H52 -> 5000 | J52: 45755 | L52: PAGADO | M52: =IF(L52="Pagado", I52, 0) -> 5000 | O52: TRANSFERENCIA | P52: =IF(L52="NO APLICA",0, (I52-M52)) -> 0
A53: 52 | B53: =Usuarios!B53 & " " & Usuarios!C53 & " " & Usuarios!D53 -> Esteban Oyarzo Levil | C53: =INDEX(INDIRECT("'" & TEXT(EDATE(J53,-2),"mm-yyyy") & "'!D:D"), MATCH(A53,INDIRECT("'" & TEXT(EDATE(J53,-2),"mm-yyyy") & "'!A:A"),0)) -> 0 | D53: 0 | E53: =D53-C53 -> 0 | F53: 1182.6 | G53: =E53*F53 -> 0 | H53: 5000 | I53: =E53*F53+H53 -> 5000 | J53: 45755 | L53: PENDIENTE | M53: =IF(L53="Pagado", I53, 0) -> 0 | P53: =IF(L53="NO APLICA",0, (I53-M53)) -> 5000
